Workbook
Name ffs_thr: Inputs!$C$31
Name min_base: Inputs!$C$8
Name neutralise: Inputs!$C$30
Name sel_area: Inputs!$C$5
Name sel_lookback: Inputs!$C$7
Name sel_year: Inputs!$C$6
Name swing_thr: Inputs!$C$32
Name target_growth: Inputs!$C$11
Name tier_a: Inputs!$C$12
Name tier_b: Inputs!$C$13
Name w_brand: Inputs!$G$20
Name w_growth: Inputs!$G$18
Name w_intensity: Inputs!$G$19
Name w_size: Inputs!$G$17

Sheet Read me
B1: Territory Targeting Model
B2: Rank the 51 US states for a therapeutic area, then split a national growth target across them.
B4: What it answers
B5: Where should a commercial team put field effort first, and how much of a growth target should each state carry? Pick an area on the Inputs sheet; the Scorecard ranks every state on four things (market size, growth, spend per enrollee, brand share) and turns the ranking into tiers A, B and C and a target for each state.
B7: How the score works
B8: Each state gets a percentile (0 to 1) on each factor among the 51. Opportunity score = 100 x the weighted average of the four percentiles. Percentiles are used instead of raw values so one huge state (California, New York) cannot swamp the others. The growth target is split in proportion to score x current spend, so a high-scoring large state carries more of it.
B10: How to use it
B11: 1) Inputs: choose the area, base year and weights (or a preset). 2) Scorecard: filter or sort; tiers are coloured. 3) Summary: the top 10, headline sentences, charts. 4) Checks: every row should read OK.
B13: Where the numbers come from
B14: CMS State Drug Utilization Data (Medicaid, public), 2019-2025, joined to the Medicaid Drug Rebate Program product list and the FDA directory so each NDC has a brand/generic flag and a therapeutic area. Enrollment is the monthly Medicaid and CHIP count (CMS), averaged per year. The full pipeline, tests and data-quality scorecard are in the repository this workbook was generated from.
B16: What to be careful about
B17: This is Medicaid only, not the whole US market. Dollars are gross reimbursed amounts before manufacturer rebates. The source blanks any state-quarter-product cell with fewer than 11 prescriptions, so state rows add up to about 92% of the national total (lower for oncology and rare disease) (see the coverage line on Inputs); rare-disease areas are the most affected. Spend per enrollee uses total Medicaid and CHIP enrollment, not the number of patients with the condition. Puerto Rico is left out (reported from 2023 only, no enrollment series).
... B23: Yellow cells with blue text are inputs. Everything else is a formula. Grey tabs are data.

Sheet Inputs
B1: Inputs
B2: Change the yellow cells. Everything else in the workbook recalculates.
B4: Market
B5: Therapeutic area | C5: All areas | D5: Which part of the market to score. 'All areas' scores total spend.
B6: Base year | C6: 2025 | D6: The year whose spend is being ranked (2019-2025).
B7: Growth look-back (years) | C7: 3 | D7: Growth is the compound annual rate over this many years, ending in the base year.
B8: Minimum prior-year spend ($) | C8: 1000000 | D8: Below this, growth is too noisy to rank, so the state gets the median growth.
B10: Target
B11: National growth target | C11: 0.08 | D11: The extra spend the team is asked to win next year, as a share of the base year. Split across states below.
B12: Tier A: number of states | C12: 10 | D12: Tier A gets first call on field resources; B is maintained; C is served remotely. Rest of the 51 are tier C.
B13: Tier B: number of states | C13: 20
B15: Score weights
B16: Factor | C16: Balanced | D16: Growth-led | E16: Size-led | F16: Custom | G16: In use
B17: Market size (spend) | C17: 0.35 | D17: 0.2 | E17: 0.55 | F17: 0.25 | G17: =INDEX(C17:F17,MATCH($C$22,$C$16:$F$16,0)) -> 0.35
B18: Growth | C18: 0.25 | D18: 0.45 | E18: 0.1 | F18: 0.25 | G18: =INDEX(C18:F18,MATCH($C$22,$C$16:$F$16,0)) -> 0.25
B19: Intensity (spend per enrollee) | C19: 0.2 | D19: 0.2 | E19: 0.2 | F19: 0.25 | G19: =INDEX(C19:F19,MATCH($C$22,$C$16:$F$16,0)) -> 0.2
B20: Brand share of spend | C20: 0.2 | D20: 0.15 | E20: 0.15 | F20: 0.25 | G20: =INDEX(C20:F20,MATCH($C$22,$C$16:$F$16,0)) -> 0.2
B21: Total (must be 100%) | C21: =SUM(C17:C20) -> 1 | D21: =SUM(D17:D20) -> 1 | E21: =SUM(E17:E20) -> 1 | F21: =SUM(F17:F20) -> 1 | G21: =SUM(G17:G20) -> 1 | H21: =IF(ROUND(G21,6)=1,"OK","Weights in use do not add to 100%: scores are not comparable") -> OK
B22: Scenario | C22: Balanced | D22: Pick a preset, or 'Custom' to use the Custom column. 'In use' follows this choice.
B24: Read-outs
B25: National spend, selected area and year | C25: =SUMIFS(National!$C$2:$C$120,National!$A$2:$A$120,$C$6,National!$B$2:$B$120,IF($C$5="All areas","*",$C$5)) -> 1.1689157e+11
B26: Sum of the 51 states, same selection | C26: =SUM(Scorecard!D7:D57) -> 1.0710013e+11
B27: State coverage of national spend | C27: =IF(C25>0,C26/C25,0) -> 0.91623487 | D27: =IF(C27<0.85,"Low coverage: the source blanks small cells in state rows, so state totals understate this area. Treat ranks with care.","Coverage is usual for this source (state rows miss the small cells the source blanks).") -> Coverage is usual for this source (state rows miss the small cells the source blanks).
B29: Reporting breaks
B30: Neutralise growth where reporting changed | C30: Yes | D30: A state flagged 'Check' on the Scorecard gets the median growth instead of its own, so a bookkeeping change is not scored as demand.
B31: Flag: fee-for-service share moves by at least | C31: 0.25 | D31: States move pharmacy spend between managed-care plans and state fee-for-service (California 2022, New York 2023); totals shift with no change in demand.
B32: Flag: year-on-year swing of at least | C32: 0.4 | D32: Any single year in the look-back window where a state's total spend moves by this much, up or down.

Sheet Scorecard
A1: Scorecard
A2: ="Scoring "&sel_area&" in "&sel_year&": growth over "&sel_lookback&" year(s), weights: "&Inputs!$C$22 -> Scoring All areas in 2025: growth over 3 year(s), weights: Balanced
A3: Percentile columns run 0 (lowest of the 51 states) to 1 (highest). Score = weighted average of the four percentiles x 100.
B6: State | C6: Region | D6: Spend (base year) | E6: Spend (prior) | F6: Growth p.a. | G6: Growth used | H6: Enrollment | I6: Spend per enrollee | J6: Brand share | K6: Size pctl | L6: Growth pctl | M6: Intensity pctl | N6: Brand pctl | O6: Opportunity score | P6: Rank | Q6: Tier | R6: Weight (score x spend) | S6: Target spend | T6: Target growth | U6: FFS share (base) | V6: FFS share (prior) | W6: Largest yr-on-yr swing | X6: Reporting flag
A7: AL | B7: Alabama | C7: South | D7: =SUMIFS(Data!$D$2:$D$6070,Data!$A$2:$A$6070,$A7,Data!$B$2:$B$6070,sel_year,Data!$C$2:$C$6070,IF(sel_area="All areas","*",sel_area)) -> 1.0379621e+09 | E7: =SUMIFS(Data!$D$2:$D$6070,Data!$A$2:$A$6070,$A7,Data!$B$2:$B$6070,sel_year-sel_lookback,Data!$C$2:$C$6070,IF(sel_area="All areas","*",sel_area)) -> 1.0564154e+09 | F7: =IF(E7>0,(D7/E7)^(1/sel_lookback)-1,"") -> -0.0058568551 | G7: =IF(AND(E7>=min_base,ISNUMBER(F7),NOT(AND(neutralise="Yes",X7="Check"))),F7,MEDIAN($F$7:$F$57)) -> -0.0058568551 | H7: =SUMIFS(Enrollment!$C$2:$C$358,Enrollment!$A$2:$A$358,$A7,Enrollment!$B$2:$B$358,sel_year) -> 950188 | I7: =IF(H7>0,D7/H7,0) -> 1092.3755 | J7: =IF(D7>0,SUMIFS(Data!$F$2:$F$6070,Data!$A$2:$A$6070,$A7,Data!$B$2:$B$6070,sel_year,Data!$C$2:$C$6070,IF(sel_area="All areas","*",sel_area))/D7,0) -> 0.87096344 | K7: =_xlfn.PERCENTRANK.INC($D$7:$D$57,D7) -> 0.5 | L7: =_xlfn.PERCENTRANK.INC($G$7:$G$57,G7) -> 0.28 | M7: =_xlfn.PERCENTRANK.INC($I$7:$I$57,I7) -> 0.34 | N7: =_xlfn.PERCENTRANK.INC($J$7:$J$57,J7) -> 0.34 | O7: =100*(w_size*K7+w_growth*L7+w_intensity*M7+w_brand*N7)+ROW()/1000000 -> 38.100007 | P7: =_xlfn.RANK.EQ(O7,$O$7:$O$57) -> 37 | Q7: =IF(P7<=tier_a,"A",IF(P7<=tier_a+tier_b,"B","C")) -> C | R7: =O7*D7 -> 3.9546362e+10 | S7: =D7+SUM($D$7:$D$57)*target_growth*R7/SUM($R$7:$R$57) -> 1.0861958e+09 | T7: =IF(D7>0,S7/D7-1,"") -> 0.046469676 | U7: =SUMIFS(Flags!$C$2:$C$358,Flags!$A$2:$A$358,$A7,Flags!$B$2:$B$358,sel_year) -> 1 | V7: =SUMIFS(Flags!$C$2:$C$358,Flags!$A$2:$A$358,$A7,Flags!$B$2:$B$358,sel_year-sel_lookback) -> 1 | W7: =_xlfn.MAXIFS(Flags!$E$2:$E$358,Flags!$A$2:$A$358,$A7,Flags!$B$2:$B$358,">"&(sel_year-sel_lookback),Flags!$B$2:$B$358,"<="&sel_year) -> 0.0687 | X7: =IF(OR(ABS(U7-V7)>=ffs_thr,W7>=swing_thr),"Check","")
A8: AK | B8: Alaska | C8: West | D8: =SUMIFS(Data!$D$2:$D$6070,Data!$A$2:$A$6070,$A8,Data!$B$2:$B$6070,sel_year,Data!$C$2:$C$6070,IF(sel_area="All areas","*",sel_area)) -> 2.1251505e+08 | E8: =SUMIFS(Data!$D$2:$D$6070,Data!$A$2:$A$6070,$A8,Data!$B$2:$B$6070,sel_year-sel_lookback,Data!$C$2:$C$6070,IF(sel_area="All areas","*",sel_area)) -> 2.1526301e+08 | F8: =IF(E8>0,(D8/E8)^(1/sel_lookback)-1,"") -> -0.0042734252 | G8: =IF(AND(E8>=min_base,ISNUMBER(F8),NOT(AND(neutralise="Yes",X8="Check"))),F8,MEDIAN($F$7:$F$57)) -> -0.0042734252 | H8: =SUMIFS(Enrollment!$C$2:$C$358,Enrollment!$A$2:$A$358,$A8,Enrollment!$B$2:$B$358,sel_year) -> 226314 | I8: =IF(H8>0,D8/H8,0) -> 939.02742 | J8: =IF(D8>0,SUMIFS(Data!$F$2:$F$6070,Data!$A$2:$A$6070,$A8,Data!$B$2:$B$6070,sel_year,Data!$C$2:$C$6070,IF(sel_area="All areas","*",sel_area))/D8,0) -> 0.8630823 | K8: =_xlfn.PERCENTRANK.INC($D$7:$D$57,D8) -> 0.06 | L8: =_xlfn.PERCENTRANK.INC($G$7:$G$57,G8) -> 0.3 | M8: =_xlfn.PERCENTRANK.INC($I$7:$I$57,I8) -> 0.16 | N8: =_xlfn.PERCENTRANK.INC($J$7:$J$57,J8) -> 0.22 | O8: =100*(w_size*K8+w_growth*L8+w_intensity*M8+w_brand*N8)+ROW()/1000000 -> 17.200008 | P8: =_xlfn.RANK.EQ(O8,$O$7:$O$57) -> 48 | Q8: =IF(P8<=tier_a,"A",IF(P8<=tier_a+tier_b,"B","C")) -> C | R8: =O8*D8 -> 3.6552606e+09 | S8: =D8+SUM($D$7:$D$57)*target_growth*R8/SUM($R$7:$R$57) -> 2.1697329e+08 | T8: =IF(D8>0,S8/D8-1,"") -> 0.020978442 | U8: =SUMIFS(Flags!$C$2:$C$358,Flags!$A$2:$A$358,$A8,Flags!$B$2:$B$358,sel_year) -> 0.9999 | V8: =SUMIFS(Flags!$C$2:$C$358,Flags!$A$2:$A$358,$A8,Flags!$B$2:$B$358,sel_year-sel_lookback) -> 1 | W8: =_xlfn.MAXIFS(Flags!$E$2:$E$358,Flags!$A$2:$A$358,$A8,Flags!$B$2:$B$358,">"&(sel_year-sel_lookback),Flags!$B$2:$B$358,"<="&sel_year) -> 0.0218 | X8: =IF(OR(ABS(U8-V8)>=ffs_thr,W8>=swing_thr),"Check","")
A9: AZ | B9: Arizona | C9: West | D9: =SUMIFS(Data!$D$2:$D$6070,Data!$A$2:$A$6070,$A9,Data!$B$2:$B$6070,sel_year,Data!$C$2:$C$6070,IF(sel_area="All areas","*",sel_area)) -> 2.057285e+09 | E9: =SUMIFS(Data!$D$2:$D$6070,Data!$A$2:$A$6070,$A9,Data!$B$2:$B$6070,sel_year-sel_lookback,Data!$C$2:$C$6070,IF(sel_area="All areas","*",sel_area)) -> 1.9793424e+09 | F9: =IF(E9>0,(D9/E9)^(1/sel_lookback)-1,"") -> 0.012957403 | G9: =IF(AND(E9>=min_base,ISNUMBER(F9),NOT(AND(neutralise="Yes",X9="Check"))),F9,MEDIAN($F$7:$F$57)) -> 0.012957403 | H9: =SUMIFS(Enrollment!$C$2:$C$358,Enrollment!$A$2:$A$358,$A9,Enrollment!$B$2:$B$358,sel_year) -> 1784205 | I9: =IF(H9>0,D9/H9,0) -> 1153.0542 | J9: =IF(D9>0,SUMIFS(Data!$F$2:$F$6070,Data!$A$2:$A$6070,$A9,Data!$B$2:$B$6070,sel_year,Data!$C$2:$C$6070,IF(sel_area="All areas","*",sel_area))/D9,0) -> 0.89102937 | K9: =_xlfn.PERCENTRANK.INC($D$7:$D$57,D9) -> 0.7 | L9: =_xlfn.PERCENTRANK.INC($G$7:$G$57,G9) -> 0.48 | M9: =_xlfn.PERCENTRANK.INC($I$7:$I$57,I9) -> 0.44 | N9: =_xlfn.PERCENTRANK.INC($J$7:$J$57,J9) -> 0.56 | O9: =100*(w_size*K9+w_growth*L9+w_intensity*M9+w_brand*N9)+ROW()/1000000 -> 56.500009 | P9: =_xlfn.RANK.EQ(O9,$O$7:$O$57) -> 18 | Q9: =IF(P9<=tier_a,"A",IF(P9<=tier_a+tier_b,"B","C")) -> B | R9: =O9*D9 -> 1.1623662e+11 | S9: =D9+SUM($D$7:$D$57)*target_growth*R9/SUM($R$7:$R$57) -> 2.1990561e+09 | T9: =IF(D9>0,S9/D9-1,"") -> 0.068911723 | U9: =SUMIFS(Flags!$C$2:$C$358,Flags!$A$2:$A$358,$A9,Flags!$B$2:$B$358,sel_year) -> 0.0282 | V9: =SUMIFS(Flags!$C$2:$C$358,Flags!$A$2:$A$358,$A9,Flags!$B$2:$B$358,sel_year-sel_lookback) -> 0.0175 | W9: =_xlfn.MAXIFS(Flags!$E$2:$E$358,Flags!$A$2:$A$358,$A9,Flags!$B$2:$B$358,">"&(sel_year-sel_lookback),Flags!$B$2:$B$358,"<="&sel_year) -> 0.0325 | X9: =IF(OR(ABS(U9-V9)>=ffs_thr,W9>=swing_thr),"Check","")
A10: AR | B10: Arkansas | C10: South | D10: =SUMIFS(Data!$D$2:$D$6070,Data!$A$2:$A$6070,$A10,Data!$B$2:$B$6070,sel_year,Data!$C$2:$C$6070,IF(sel_area="All areas","*",sel_area)) -> 4.9912955e+08 | E10: =SUMIFS(Data!$D$2:$D$6070,Data!$A$2:$A$6070,$A10,Data!$B$2:$B$6070,sel_year-sel_lookback,Data!$C$2:$C$6070,IF(sel_area="All areas","*",sel_area)) -> 5.2058631e+08 | F10: =IF(E10>0,(D10/E10)^(1/sel_lookback)-1,"") -> -0.013932044 | G10: =IF(AND(E10>=min_base,ISNUMBER(F10),NOT(AND(neutralise="Yes",X10="Check"))),F10,MEDIAN($F$7:$F$57)) -> -0.013932044 | H10: =SUMIFS(Enrollment!$C$2:$C$358,Enrollment!$A$2:$A$358,$A10,Enrollment!$B$2:$B$358,sel_year) -> 818490 | I10: =IF(H10>0,D10/H10,0) -> 609.81753 | J10: =IF(D10>0,SUMIFS(Data!$F$2:$F$6070,Data!$A$2:$A$6070,$A10,Data!$B$2:$B$6070,sel_year,Data!$C$2:$C$6070,IF(sel_area="All areas","*",sel_area))/D10,0) -> 0.84089998 | K10: =_xlfn.PERCENTRANK.INC($D$7:$D$57,D10) -> 0.24 | L10: =_xlfn.PERCENTRANK.INC($G$7:$G$57,G10) -> 0.2 | M10: =_xlfn.PERCENTRANK.INC($I$7:$I$57,I10) -> 0 | N10: =_xlfn.PERCENTRANK.INC($J$7:$J$57,J10) -> 0.1 | O10: =100*(w_size*K10+w_growth*L10+w_intensity*M10+w_brand*N10)+ROW()/1000000 -> 15.40001 | P10: =_xlfn.RANK.EQ(O10,$O$7:$O$57) -> 49 | Q10: =IF(P10<=tier_a,"A",IF(P10<=tier_a+tier_b,"B","C")) -> C | R10: =O10*D10 -> 7.6866e+09 | S10: =D10+SUM($D$7:$D$57)*target_growth*R10/SUM($R$7:$R$57) -> 5.0850471e+08 | T10: =IF(D10>0,S10/D10-1,"") -> 0.018783028 | U10: =SUMIFS(Flags!$C$2:$C$358,Flags!$A$2:$A$358,$A10,Flags!$B$2:$B$358,sel_year) -> 0.8214 | V10: =SUMIFS(Flags!$C$2:$C$358,Flags!$A$2:$A$358,$A10,Flags!$B$2:$B$358,sel_year-sel_lookback) -> 0.8091 | W10: =_xlfn.MAXIFS(Flags!$E$2:$E$358,Flags!$A$2:$A$358,$A10,Flags!$B$2:$B$358,">"&(sel_year-sel_lookback),Flags!$B$2:$B$358,"<="&sel_year) -> 0.1233 | X10: =IF(OR(ABS(U10-V10)>=ffs_thr,W10>=swing_thr),"Check","")
A11: CA | B11: California | C11: West | D11: =SUMIFS(Data!$D$2:$D$6070,Data!$A$2:$A$6070,$A11,Data!$B$2:$B$6070,sel_year,Data!$C$2:$C$6070,IF(sel_area="All areas","*",sel_area)) -> 1.8272384e+10 | E11: =SUMIFS(Data!$D$2:$D$6070,Data!$A$2:$A$6070,$A11,Data!$B$2:$B$6070,sel_year-sel_lookback,Data!$C$2:$C$6070,IF(sel_area="All areas","*",sel_area)) -> 1.2155365e+10 | F11: =IF(E11>0,(D11/E11)^(1/sel_lookback)-1,"") -> 0.14553686 | G11: =IF(AND(E11>=min_base,ISNUMBER(F11),NOT(AND(neutralise="Yes",X11="Check"))),F11,MEDIAN($F$7:$F$57)) -> 0.14553686 | H11: =SUMIFS(Enrollment!$C$2:$C$358,Enrollment!$A$2:$A$358,$A11,Enrollment!$B$2:$B$358,sel_year) -> 13275327 | I11: =IF(H11>0,D11/H11,0) -> 1376.4168 | J11: =IF(D11>0,SUMIFS(Data!$F$2:$F$6070,Data!$A$2:$A$6070,$A11,Data!$B$2:$B$6070,sel_year,Data!$C$2:$C$6070,IF(sel_area="All areas","*",sel_area))/D11,0) -> 0.88826814 | K11: =_xlfn.PERCENTRANK.INC($D$7:$D$57,D11) -> 1 | L11: =_xlfn.PERCENTRANK.INC($G$7:$G$57,G11) -> 0.98 | M11: =_xlfn.PERCENTRANK.INC($I$7:$I$57,I11) -> 0.56 | N11: =_xlfn.PERCENTRANK.INC($J$7:$J$57,J11) -> 0.52 | O11: =100*(w_size*K11+w_growth*L11+w_intensity*M11+w_brand*N11)+ROW()/1000000 -> 81.100011 | P11: =_xlfn.RANK.EQ(O11,$O$7:$O$57) -> 3 | Q11: =IF(P11<=tier_a,"A",IF(P11<=tier_a+tier_b,"B","C")) -> A | R11: =O11*D11 -> 1.4818905e+12 | S11: =D11+SUM($D$7:$D$57)*target_growth*R11/SUM($R$7:$R$57) -> 2.007981e+10 | T11: =IF(D11>0,S11/D11-1,"") -> 0.098915763 | U11: =SUMIFS(Flags!$C$2:$C$358,Flags!$A$2:$A$358,$A11,Flags!$B$2:$B$358,sel_year) -> 0.9626 | V11: =SUMIFS(Flags!$C$2:$C$358,Flags!$A$2:$A$358,$A11,Flags!$B$2:$B$358,sel_year-sel_lookback) -> 0.9194 | W11: =_xlfn.MAXIFS(Flags!$E$2:$E$358,Flags!$A$2:$A$358,$A11,Flags!$B$2:$B$358,">"&(sel_year-sel_lookback),Flags!$B$2:$B$358,"<="&sel_year) -> 0.2319 | X11: =IF(OR(ABS(U11-V11)>=ffs_thr,W11>=swing_thr),"Check","")
A12: CO | B12: Colorado | C12: West | D12: =SUMIFS(Data!$D$2:$D$6070,Data!$A$2:$A$6070,$A12,Data!$B$2:$B$6070,sel_year,Data!$C$2:$C$6070,IF(sel_area="All areas","*",sel_area)) -> 1.6322991e+09 | E12: =SUMIFS(Data!$D$2:$D$6070,Data!$A$2:$A$6070,$A12,Data!$B$2:$B$6070,sel_year-sel_lookback,Data!$C$2:$C$6070,IF(sel_area="All areas","*",sel_area)) -> 1.4356485e+09 | F12: =IF(E12>0,(D12/E12)^(1/sel_lookback)-1,"") -> 0.043719702 | G12: =IF(AND(E12>=min_base,ISNUMBER(F12),NOT(AND(neutralise="Yes",X12="Check"))),F12,MEDIAN($F$7:$F$57)) -> 0.043719702 | H12: =SUMIFS(Enrollment!$C$2:$C$358,Enrollment!$A$2:$A$358,$A12,Enrollment!$B$2:$B$358,sel_year) -> 1206238 | I12: =IF(H12>0,D12/H12,0) -> 1353.2148 | J12: =IF(D12>0,SUMIFS(Data!$F$2:$F$6070,Data!$A$2:$A$6070,$A12,Data!$B$2:$B$6070,sel_year,Data!$C$2:$C$6070,IF(sel_area="All areas","*",sel_area))/D12,0) -> 0.90967178 | K12: =_xlfn.PERCENTRANK.INC($D$7:$D$57,D12) -> 0.58 | L12: =_xlfn.PERCENTRANK.INC($G$7:$G$57,G12) -> 0.82 | M12: =_xlfn.PERCENTRANK.INC($I$7:$I$57,I12) -> 0.52 | N12: =_xlfn.PERCENTRANK.INC($J$7:$J$57,J12) -> 0.82 | O12: =100*(w_size*K12+w_growth*L12+w_intensity*M12+w_brand*N12)+ROW()/1000000 -> 67.600012 | P12: =_xlfn.RANK.EQ(O12,$O$7:$O$57) -> 11 | Q12: =IF(P12<=tier_a,"A",IF(P12<=tier_a+tier_b,"B","C")) -> B | R12: =O12*D12 -> 1.1034344e+11 | S12: =D12+SUM($D$7:$D$57)*target_growth*R12/SUM($R$7:$R$57) -> 1.7668824e+09 | T12: =IF(D12>0,S12/D12-1,"") -> 0.082450134 | U12: =SUMIFS(Flags!$C$2:$C$358,Flags!$A$2:$A$358,$A12,Flags!$B$2:$B$358,sel_year) -> 0.9595 | V12: =SUMIFS(Flags!$C$2:$C$358,Flags!$A$2:$A$358,$A12,Flags!$B$2:$B$358,sel_year-sel_lookback) -> 0.9578 | W12: =_xlfn.MAXIFS(Flags!$E$2:$E$358,Flags!$A$2:$A$358,$A12,Flags!$B$2:$B$358,">"&(sel_year-sel_lookback),Flags!$B$2:$B$358,"<="&sel_year) -> 0.1039 | X12: =IF(OR(ABS(U12-V12)>=ffs_thr,W12>=swing_thr),"Check","")
A13: CT | B13: Connecticut | C13: Northeast | D13: =SUMIFS(Data!$D$2:$D$6070,Data!$A$2:$A$6070,$A13,Data!$B$2:$B$6070,sel_year,Data!$C$2:$C$6070,IF(sel_area="All areas","*",sel_area)) -> 1.9631671e+09 | E13: =SUMIFS(Data!$D$2:$D$6070,Data!$A$2:$A$6070,$A13,Data!$B$2:$B$6070,sel_year-sel_lookback,Data!$C$2:$C$6070,IF(sel_area="All areas","*",sel_area)) -> 1.7908683e+09 | F13: =IF(E13>0,(D13/E13)^(1/sel_lookback)-1,"") -> 0.031093076 | G13: =IF(AND(E13>=min_base,ISNUMBER(F13),NOT(AND(neutralise="Yes",X13="Check"))),F13,MEDIAN($F$7:$F$57)) -> 0.031093076 | H13: =SUMIFS(Enrollment!$C$2:$C$358,Enrollment!$A$2:$A$358,$A13,Enrollment!$B$2:$B$358,sel_year) -> 917844 | I13: =IF(H13>0,D13/H13,0) -> 2138.8897 | J13: =IF(D13>0,SUMIFS(Data!$F$2:$F$6070,Data!$A$2:$A$6070,$A13,Data!$B$2:$B$6070,sel_year,Data!$C$2:$C$6070,IF(sel_area="All areas","*",sel_area))/D13,0) -> 0.91792072 | K13: =_xlfn.PERCENTRANK.INC($D$7:$D$57,D13) -> 0.64 | L13: =_xlfn.PERCENTRANK.INC($G$7:$G$57,G13) -> 0.74 | M13: =_xlfn.PERCENTRANK.INC($I$7:$I$57,I13) -> 1 | N13: =_xlfn.PERCENTRANK.INC($J$7:$J$57,J13) -> 0.94 | O13: =100*(w_size*K13+w_growth*L13+w_intensity*M13+w_brand*N13)+ROW()/1000000 -> 79.700013 | P13: =_xlfn.RANK.EQ(O13,$O$7:$O$57) -> 5 | Q13: =IF(P13<=tier_a,"A",IF(P13<=tier_a+tier_b,"B","C")) -> A | R13: =O13*D13 -> 1.5646444e+11 | S13: =D13+SUM($D$7:$D$57)*target_growth*R13/SUM($R$7:$R$57) -> 2.1540031e+09 | T13: =IF(D13>0,S13/D13-1,"") -> 0.097208219 | U13: =SUMIFS(Flags!$C$2:$C$358,Flags!$A$2:$A$358,$A13,Flags!$B$2:$B$358,sel_year) -> 1 | V13: =SUMIFS(Flags!$C$2:$C$358,Flags!$A$2:$A$358,$A13,Flags!$B$2:$B$358,sel_year-sel_lookback) -> 1 | W13: =_xlfn.MAXIFS(Flags!$E$2:$E$358,Flags!$A$2:$A$358,$A13,Flags!$B$2:$B$358,">"&(sel_year-sel_lookback),Flags!$B$2:$B$358,"<="&sel_year) -> 0.0856 | X13: =IF(OR(ABS(U13-V13)>=ffs_thr,W13>=swing_thr),"Check","")
A14: DE | B14: Delaware | C14: South | D14: =SUMIFS(Data!$D$2:$D$6070,Data!$A$2:$A$6070,$A14,Data!$B$2:$B$6070,sel_year,Data!$C$2:$C$6070,IF(sel_area="All areas","*",sel_area)) -> 2.7306339e+08 | E14: =SUMIFS(Data!$D$2:$D$6070,Data!$A$2:$A$6070,$A14,Data!$B$2:$B$6070,sel_year-sel_lookback,Data!$C$2:$C$6070,IF(sel_area="All areas","*",sel_area)) -> 2.9478095e+08 | F14: =IF(E14>0,(D14/E14)^(1/sel_lookback)-1,"") -> -0.025186902 | G14: =IF(AND(E14>=min_base,ISNUMBER(F14),NOT(AND(neutralise="Yes",X14="Check"))),F14,MEDIAN($F$7:$F$57)) -> -0.025186902 | H14: =SUMIFS(Enrollment!$C$2:$C$358,Enrollment!$A$2:$A$358,$A14,Enrollment!$B$2:$B$358,sel_year) -> 244713 | I14: =IF(H14>0,D14/H14,0) -> 1115.8516 | J14: =IF(D14>0,SUMIFS(Data!$F$2:$F$6070,Data!$A$2:$A$6070,$A14,Data!$B$2:$B$6070,sel_year,Data!$C$2:$C$6070,IF(sel_area="All areas","*",sel_area))/D14,0) -> 0.88607832 | K14: =_xlfn.PERCENTRANK.INC($D$7:$D$57,D14) -> 0.12 | L14: =_xlfn.PERCENTRANK.INC($G$7:$G$57,G14) -> 0.18 | M14: =_xlfn.PERCENTRANK.INC($I$7:$I$57,I14) -> 0.38 | N14: =_xlfn.PERCENTRANK.INC($J$7:$J$57,J14) -> 0.46 | O14: =100*(w_size*K14+w_growth*L14+w_intensity*M14+w_brand*N14)+ROW()/1000000 -> 25.500014 | P14: =_xlfn.RANK.EQ(O14,$O$7:$O$57) -> 44 | Q14: =IF(P14<=tier_a,"A",IF(P14<=tier_a+tier_b,"B","C")) -> C | R14: =O14*D14 -> 6.9631202e+09 | S14: =D14+SUM($D$7:$D$57)*target_growth*R14/SUM($R$7:$R$57) -> 2.8155614e+08 | T14: =IF(D14>0,S14/D14-1,"") -> 0.031101763 | U14: =SUMIFS(Flags!$C$2:$C$358,Flags!$A$2:$A$358,$A14,Flags!$B$2:$B$358,sel_year) -> 0.0051 | V14: =SUMIFS(Flags!$C$2:$C$358,Flags!$A$2:$A$358,$A14,Flags!$B$2:$B$358,sel_year-sel_lookback) -> 0.0054 | W14: =_xlfn.MAXIFS(Flags!$E$2:$E$358,Flags!$A$2:$A$358,$A14,Flags!$B$2:$B$358,">"&(sel_year-sel_lookback),Flags!$B$2:$B$358,"<="&sel_year) -> 0.1007 | X14: =IF(OR(ABS(U14-V14)>=ffs_thr,W14>=swing_thr),"Check","")
A15: DC | B15: District of Columbia | C15: South | D15: =SUMIFS(Data!$D$2:$D$6070,Data!$A$2:$A$6070,$A15,Data!$B$2:$B$6070,sel_year,Data!$C$2:$C$6070,IF(sel_area="All areas","*",sel_area)) -> 3.2493547e+08 | E15: =SUMIFS(Data!$D$2:$D$6070,Data!$A$2:$A$6070,$A15,Data!$B$2:$B$6070,sel_year-sel_lookback,Data!$C$2:$C$6070,IF(sel_area="All areas","*",sel_area)) -> 3.2422056e+08 | F15: =IF(E15>0,(D15/E15)^(1/sel_lookback)-1,"") -> 0.00073445666 | G15: =IF(AND(E15>=min_base,ISNUMBER(F15),NOT(AND(neutralise="Yes",X15="Check"))),F15,MEDIAN($F$7:$F$57)) -> 0.00073445666 | H15: =SUMIFS(Enrollment!$C$2:$C$358,Enrollment!$A$2:$A$358,$A15,Enrollment!$B$2:$B$358,sel_year) -> 259736 | I15: =IF(H15>0,D15/H15,0) -> 1251.0221 | J15: =IF(D15>0,SUMIFS(Data!$F$2:$F$6070,Data!$A$2:$A$6070,$A15,Data!$B$2:$B$6070,sel_year,Data!$C$2:$C$6070,IF(sel_area="All areas","*",sel_area))/D15,0) -> 0.9275696 | K15: =_xlfn.PERCENTRANK.INC($D$7:$D$57,D15) -> 0.18 | L15: =_xlfn.PERCENTRANK.INC($G$7:$G$57,G15) -> 0.36 | M15: =_xlfn.PERCENTRANK.INC($I$7:$I$57,I15) -> 0.5 | N15: =_xlfn.PERCENTRANK.INC($J$7:$J$57,J15) -> 1 | O15: =100*(w_size*K15+w_growth*L15+w_intensity*M15+w_brand*N15)+ROW()/1000000 -> 45.300015 | P15: =_xlfn.RANK.EQ(O15,$O$7:$O$57) -> 32 | Q15: =IF(P15<=tier_a,"A",IF(P15<=tier_a+tier_b,"B","C")) -> C | R15: =O15*D15 -> 1.4719582e+10 | S15: =D15+SUM($D$7:$D$57)*target_growth*R15/SUM($R$7:$R$57) -> 3.4288859e+08 | T15: =IF(D15>0,S15/D15-1,"") -> 0.055251356 | U15: =SUMIFS(Flags!$C$2:$C$358,Flags!$A$2:$A$358,$A15,Flags!$B$2:$B$358,sel_year) -> 0.4732 | V15: =SUMIFS(Flags!$C$2:$C$358,Flags!$A$2:$A$358,$A15,Flags!$B$2:$B$358,sel_year-sel_lookback) -> 0.4432 | W15: =_xlfn.MAXIFS(Flags!$E$2:$E$358,Flags!$A$2:$A$358,$A15,Flags!$B$2:$B$358,">"&(sel_year-sel_lookback),Flags!$B$2:$B$358,"<="&sel_year) -> 0.1624 | X15: =IF(OR(ABS(U15-V15)>=ffs_thr,W15>=swing_thr),"Check","")
A16: FL | B16: Florida | C16: South | D16: =SUMIFS(Data!$D$2:$D$6070,Data!$A$2:$A$6070,$A16,Data!$B$2:$B$6070,sel_year,Data!$C$2:$C$6070,IF(sel_area="All areas","*",sel_area)) -> 3.2549463e+09 | E16: =SUMIFS(Data!$D$2:$D$6070,Data!$A$2:$A$6070,$A16,Data!$B$2:$B$6070,sel_year-sel_lookback,Data!$C$2:$C$6070,IF(sel_area="All areas","*",sel_area)) -> 3.8157803e+09 | F16: =IF(E16>0,(D16/E16)^(1/sel_lookback)-1,"") -> -0.051610321 | G16: =IF(AND(E16>=min_base,ISNUMBER(F16),NOT(AND(neutralise="Yes",X16="Check"))),F16,MEDIAN($F$7:$F$57)) -> -0.051610321 | H16: =SUMIFS(Enrollment!$C$2:$C$358,Enrollment!$A$2:$A$358,$A16,Enrollment!$B$2:$B$358,sel_year) -> 3679966 | I16: =IF(H16>0,D16/H16,0) -> 884.50444 | J16: =IF(D16>0,SUMIFS(Data!$F$2:$F$6070,Data!$A$2:$A$6070,$A16,Data!$B$2:$B$6070,sel_year,Data!$C$2:$C$6070,IF(sel_area="All areas","*",sel_area))/D16,0) -> 0.91437795 | K16: =_xlfn.PERCENTRANK.INC($D$7:$D$57,D16) -> 0.84 | L16: =_xlfn.PERCENTRANK.INC($G$7:$G$57,G16) -> 0.04 | M16: =_xlfn.PERCENTRANK.INC($I$7:$I$57,I16) -> 0.1 | N16: =_xlfn.PERCENTRANK.INC($J$7:$J$57,J16) -> 0.88 | O16: =100*(w_size*K16+w_growth*L16+w_intensity*M16+w_brand*N16)+ROW()/1000000 -> 50.000016 | P16: =_xlfn.RANK.EQ(O16,$O$7:$O$57) -> 27 | Q16: =IF(P16<=tier_a,"A",IF(P16<=tier_a+tier_b,"B","C")) -> B | R16: =O16*D16 -> 1.6274737e+11 | S16: =D16+SUM($D$7:$D$57)*target_growth*R16/SUM($R$7:$R$57) -> 3.4534454e+09 | T16: =IF(D16>0,S16/D16-1,"") -> 0.060983836 | U16: =SUMIFS(Flags!$C$2:$C$358,Flags!$A$2:$A$358,$A16,Flags!$B$2:$B$358,sel_year) -> 0.0533 | V16: =SUMIFS(Flags!$C$2:$C$358,Flags!$A$2:$A$358,$A16,Flags!$B$2:$B$358,sel_year-sel_lookback) -> 0.0684 | W16: =_xlfn.MAXIFS(Flags!$E$2:$E$358,Flags!$A$2:$A$358,$A16,Flags!$B$2:$B$358,">"&(sel_year-sel_lookback),Flags!$B$2:$B$358,"<="&sel_year) -> 0.175 | X16: =IF(OR(ABS(U16-V16)>=ffs_thr,W16>=swing_thr),"Check","")
A17: GA | B17: Georgia | C17: South | D17: =SUMIFS(Data!$D$2:$D$6070,Data!$A$2:$A$6070,$A17,Data!$B$2:$B$6070,sel_year,Data!$C$2:$C$6070,IF(sel_area="All areas","*",sel_area)) -> 1.3068258e+09 | E17: =SUMIFS(Data!$D$2:$D$6070,Data!$A$2:$A$6070,$A17,Data!$B$2:$B$6070,sel_year-sel_lookback,Data!$C$2:$C$6070,IF(sel_area="All areas","*",sel_area)) -> 1.4730917e+09 | F17: =IF(E17>0,(D17/E17)^(1/sel_lookback)-1,"") -> -0.039134421 | G17: =IF(AND(E17>=min_base,ISNUMBER(F17),NOT(AND(neutralise="Yes",X17="Check"))),F17,MEDIAN($F$7:$F$57)) -> -0.039134421 | H17: =SUMIFS(Enrollment!$C$2:$C$358,Enrollment!$A$2:$A$358,$A17,Enrollment!$B$2:$B$358,sel_year) -> 1918828 | I17: =IF(H17>0,D17/H17,0) -> 681.05416 | J17: =IF(D17>0,SUMIFS(Data!$F$2:$F$6070,Data!$A$2:$A$6070,$A17,Data!$B$2:$B$6070,sel_year,Data!$C$2:$C$6070,IF(sel_area="All areas","*",sel_area))/D17,0) -> 0.88701841 | K17: =_xlfn.PERCENTRANK.INC($D$7:$D$57,D17) -> 0.52 | L17: =_xlfn.PERCENTRANK.INC($G$7:$G$57,G17) -> 0.06 | M17: =_xlfn.PERCENTRANK.INC($I$7:$I$57,I17) -> 0.04 | N17: =_xlfn.PERCENTRANK.INC($J$7:$J$57,J17) -> 0.5 | O17: =100*(w_size*K17+w_growth*L17+w_intensity*M17+w_brand*N17)+ROW()/1000000 -> 30.500017 | P17: =_xlfn.RANK.EQ(O17,$O$7:$O$57) -> 41 | Q17: =IF(P17<=tier_a,"A",IF(P17<=tier_a+tier_b,"B","C")) -> C | R17: =O17*D17 -> 3.9858209e+10 | S17: =D17+SUM($D$7:$D$57)*target_growth*R17/SUM($R$7:$R$57) -> 1.3554399e+09 | T17: =IF(D17>0,S17/D17-1,"") -> 0.037200149 | U17: =SUMIFS(Flags!$C$2:$C$358,Flags!$A$2:$A$358,$A17,Flags!$B$2:$B$358,sel_year) -> 0.6371 | V17: =SUMIFS(Flags!$C$2:$C$358,Flags!$A$2:$A$358,$A17,Flags!$B$2:$B$358,sel_year-sel_lookback) -> 0.6212 | W17: =_xlfn.MAXIFS(Flags!$E$2:$E$358,Flags!$A$2:$A$358,$A17,Flags!$B$2:$B$358,">"&(sel_year-sel_lookback),Flags!$B$2:$B$358,"<="&sel_year) -> 0.1407 | X17: =IF(OR(ABS(U17-V17)>=ffs_thr,W17>=swing_thr),"Check","")
A18: HI | B18: Hawaii | C18: West | D18: =SUMIFS(Data!$D$2:$D$6070,Data!$A$2:$A$6070,$A18,Data!$B$2:$B$6070,sel_year,Data!$C$2:$C$6070,IF(sel_area="All areas","*",sel_area)) -> 2.642765e+08 | E18: =SUMIFS(Data!$D$2:$D$6070,Data!$A$2:$A$6070,$A18,Data!$B$2:$B$6070,sel_year-sel_lookback,Data!$C$2:$C$6070,IF(sel_area="All areas","*",sel_area)) -> 2.3146846e+08 | F18: =IF(E18>0,(D18/E18)^(1/sel_lookback)-1,"") -> 0.045174736 | G18: =IF(AND(E18>=min_base,ISNUMBER(F18),NOT(AND(neutralise="Yes",X18="Check"))),F18,MEDIAN($F$7:$F$57)) -> 0.045174736 | H18: =SUMIFS(Enrollment!$C$2:$C$358,Enrollment!$A$2:$A$358,$A18,Enrollment!$B$2:$B$358,sel_year) -> 395096 | I18: =IF(H18>0,D18/H18,0) -> 668.89186 | J18: =IF(D18>0,SUMIFS(Data!$F$2:$F$6070,Data!$A$2:$A$6070,$A18,Data!$B$2:$B$6070,sel_year,Data!$C$2:$C$6070,IF(sel_area="All areas","*",sel_area))/D18,0) -> 0.89886541 | K18: =_xlfn.PERCENTRANK.INC($D$7:$D$57,D18) -> 0.08 | L18: =_xlfn.PERCENTRANK.INC($G$7:$G$57,G18) -> 0.84 | M18: =_xlfn.PERCENTRANK.INC($I$7:$I$57,I18) -> 0.02 | N18: =_xlfn.PERCENTRANK.INC($J$7:$J$57,J18) -> 0.7 | O18: =100*(w_size*K18+w_growth*L18+w_intensity*M18+w_brand*N18)+ROW()/1000000 -> 38.200018 | P18: =_xlfn.RANK.EQ(O18,$O$7:$O$57) -> 36 | Q18: =IF(P18<=tier_a,"A",IF(P18<=tier_a+tier_b,"B","C")) -> C | R18: =O18*D18 -> 1.0095367e+10 | S18: =D18+SUM($D$7:$D$57)*target_growth*R18/SUM($R$7:$R$57) -> 2.7658958e+08 | T18: =IF(D18>0,S18/D18-1,"") -> 0.046591657 | U18: =SUMIFS(Flags!$C$2:$C$358,Flags!$A$2:$A$358,$A18,Flags!$B$2:$B$358,sel_year) -> 0.0015 | V18: =SUMIFS(Flags!$C$2:$C$358,Flags!$A$2:$A$358,$A18,Flags!$B$2:$B$358,sel_year-sel_lookback) -> 0.0003 | W18: =_xlfn.MAXIFS(Flags!$E$2:$E$358,Flags!$A$2:$A$358,$A18,Flags!$B$2:$B$358,">"&(sel_year-sel_lookback),Flags!$B$2:$B$358,"<="&sel_year) -> 0.2165 | X18: =IF(OR(ABS(U18-V18)>=ffs_thr,W18>=swing_thr),"Check","")
... A57: WY | B57: Wyoming | C57: West | D57: =SUMIFS(Data!$D$2:$D$6070,Data!$A$2:$A$6070,$A57,Data!$B$2:$B$6070,sel_year,Data!$C$2:$C$6070,IF(sel_area="All areas","*",sel_area)) -> 42961809 | E57: =SUMIFS(Data!$D$2:$D$6070,Data!$A$2:$A$6070,$A57,Data!$B$2:$B$6070,sel_year-sel_lookback,Data!$C$2:$C$6070,IF(sel_area="All areas","*",sel_area)) -> 47276171 | F57: =IF(E57>0,(D57/E57)^(1/sel_lookback)-1,"") -> -0.031394893 | G57: =IF(AND(E57>=min_base,ISNUMBER(F57),NOT(AND(neutralise="Yes",X57="Check"))),F57,MEDIAN($F$7:$F$57)) -> -0.031394893 | H57: =SUMIFS(Enrollment!$C$2:$C$358,Enrollment!$A$2:$A$358,$A57,Enrollment!$B$2:$B$358,sel_year) -> 62025 | I57: =IF(H57>0,D57/H57,0) -> 692.6531 | J57: =IF(D57>0,SUMIFS(Data!$F$2:$F$6070,Data!$A$2:$A$6070,$A57,Data!$B$2:$B$6070,sel_year,Data!$C$2:$C$6070,IF(sel_area="All areas","*",sel_area))/D57,0) -> 0.86583177 | K57: =_xlfn.PERCENTRANK.INC($D$7:$D$57,D57) -> 0 | L57: =_xlfn.PERCENTRANK.INC($G$7:$G$57,G57) -> 0.12 | M57: =_xlfn.PERCENTRANK.INC($I$7:$I$57,I57) -> 0.06 | N57: =_xlfn.PERCENTRANK.INC($J$7:$J$57,J57) -> 0.24 | O57: =100*(w_size*K57+w_growth*L57+w_intensity*M57+w_brand*N57)+ROW()/1000000 -> 9.000057 | P57: =_xlfn.RANK.EQ(O57,$O$7:$O$57) -> 51 | Q57: =IF(P57<=tier_a,"A",IF(P57<=tier_a+tier_b,"B","C")) -> C | R57: =O57*D57 -> 3.8665873e+08 | S57: =D57+SUM($D$7:$D$57)*target_growth*R57/SUM($R$7:$R$57) -> 43433407 | T57: =IF(D57>0,S57/D57-1,"") -> 0.010977156 | U57: =SUMIFS(Flags!$C$2:$C$358,Flags!$A$2:$A$358,$A57,Flags!$B$2:$B$358,sel_year) -> 1 | V57: =SUMIFS(Flags!$C$2:$C$358,Flags!$A$2:$A$358,$A57,Flags!$B$2:$B$358,sel_year-sel_lookback) -> 1 | W57: =_xlfn.MAXIFS(Flags!$E$2:$E$358,Flags!$A$2:$A$358,$A57,Flags!$B$2:$B$358,">"&(sel_year-sel_lookback),Flags!$B$2:$B$358,"<="&sel_year) -> 0.1757 | X57: =IF(OR(ABS(U57-V57)>=ffs_thr,W57>=swing_thr),"Check","")
B58: All 51 states | D58: =SUM(D7:D57) -> 1.0710013e+11 | E58: =SUM(E7:E57) -> 9.376314e+10 | H58: =SUM(H7:H57) -> 78052004 | S58: =SUM(S7:S57) -> 1.1566814e+11 | T58: =IF(D58>0,S58/D58-1,"") -> 0.08

Sheet Summary
B1: Summary
B2: =sel_area&", "&sel_year&" - top 10 states by opportunity score" -> All areas, 2025 - top 10 states by opportunity score
B4: Rank | C4: State | D4: Score | E4: Spend | F4: Growth p.a. | G4: Tier | H4: Reporting
B5: 1 | C5: =INDEX(Scorecard!$B$7:$B$57,MATCH($B5,Scorecard!$P$7:$P$57,0)) -> Michigan | D5: =INDEX(Scorecard!$O$7:$O$57,MATCH($B5,Scorecard!$P$7:$P$57,0)) -> 90.300029 | E5: =INDEX(Scorecard!$D$7:$D$57,MATCH($B5,Scorecard!$P$7:$P$57,0)) -> 4.170522e+09 | F5: =INDEX(Scorecard!$G$7:$G$57,MATCH($B5,Scorecard!$P$7:$P$57,0)) -> 0.048405452 | G5: =INDEX(Scorecard!$Q$7:$Q$57,MATCH($B5,Scorecard!$P$7:$P$57,0)) -> A | H5: =IF(INDEX(Scorecard!$X$7:$X$57,MATCH($B5,Scorecard!$P$7:$P$57,0))="Check","Check","")
B6: 2 | C6: =INDEX(Scorecard!$B$7:$B$57,MATCH($B6,Scorecard!$P$7:$P$57,0)) -> Pennsylvania | D6: =INDEX(Scorecard!$O$7:$O$57,MATCH($B6,Scorecard!$P$7:$P$57,0)) -> 87.100045 | E6: =INDEX(Scorecard!$D$7:$D$57,MATCH($B6,Scorecard!$P$7:$P$57,0)) -> 5.3680051e+09 | F6: =INDEX(Scorecard!$G$7:$G$57,MATCH($B6,Scorecard!$P$7:$P$57,0)) -> 0.046085864 | G6: =INDEX(Scorecard!$Q$7:$Q$57,MATCH($B6,Scorecard!$P$7:$P$57,0)) -> A | H6: =IF(INDEX(Scorecard!$X$7:$X$57,MATCH($B6,Scorecard!$P$7:$P$57,0))="Check","Check","")
B7: 3 | C7: =INDEX(Scorecard!$B$7:$B$57,MATCH($B7,Scorecard!$P$7:$P$57,0)) -> California | D7: =INDEX(Scorecard!$O$7:$O$57,MATCH($B7,Scorecard!$P$7:$P$57,0)) -> 81.100011 | E7: =INDEX(Scorecard!$D$7:$D$57,MATCH($B7,Scorecard!$P$7:$P$57,0)) -> 1.8272384e+10 | F7: =INDEX(Scorecard!$G$7:$G$57,MATCH($B7,Scorecard!$P$7:$P$57,0)) -> 0.14553686 | G7: =INDEX(Scorecard!$Q$7:$Q$57,MATCH($B7,Scorecard!$P$7:$P$57,0)) -> A | H7: =IF(INDEX(Scorecard!$X$7:$X$57,MATCH($B7,Scorecard!$P$7:$P$57,0))="Check","Check","")
B8: 4 | C8: =INDEX(Scorecard!$B$7:$B$57,MATCH($B8,Scorecard!$P$7:$P$57,0)) -> Massachusetts | D8: =INDEX(Scorecard!$O$7:$O$57,MATCH($B8,Scorecard!$P$7:$P$57,0)) -> 79.700028 | E8: =INDEX(Scorecard!$D$7:$D$57,MATCH($B8,Scorecard!$P$7:$P$57,0)) -> 2.5686586e+09 | F8: =INDEX(Scorecard!$G$7:$G$57,MATCH($B8,Scorecard!$P$7:$P$57,0)) -> 0.041254148 | G8: =INDEX(Scorecard!$Q$7:$Q$57,MATCH($B8,Scorecard!$P$7:$P$57,0)) -> A | H8: =IF(INDEX(Scorecard!$X$7:$X$57,MATCH($B8,Scorecard!$P$7:$P$57,0))="Check","Check","")
B9: 5 | C9: =INDEX(Scorecard!$B$7:$B$57,MATCH($B9,Scorecard!$P$7:$P$57,0)) -> Connecticut | D9: =INDEX(Scorecard!$O$7:$O$57,MATCH($B9,Scorecard!$P$7:$P$57,0)) -> 79.700013 | E9: =INDEX(Scorecard!$D$7:$D$57,MATCH($B9,Scorecard!$P$7:$P$57,0)) -> 1.9631671e+09 | F9: =INDEX(Scorecard!$G$7:$G$57,MATCH($B9,Scorecard!$P$7:$P$57,0)) -> 0.031093076 | G9: =INDEX(Scorecard!$Q$7:$Q$57,MATCH($B9,Scorecard!$P$7:$P$57,0)) -> A | H9: =IF(INDEX(Scorecard!$X$7:$X$57,MATCH($B9,Scorecard!$P$7:$P$57,0))="Check","Check","")
B10: 6 | C10: =INDEX(Scorecard!$B$7:$B$57,MATCH($B10,Scorecard!$P$7:$P$57,0)) -> Indiana | D10: =INDEX(Scorecard!$O$7:$O$57,MATCH($B10,Scorecard!$P$7:$P$57,0)) -> 78.900021 | E10: =INDEX(Scorecard!$D$7:$D$57,MATCH($B10,Scorecard!$P$7:$P$57,0)) -> 2.9303525e+09 | F10: =INDEX(Scorecard!$G$7:$G$57,MATCH($B10,Scorecard!$P$7:$P$57,0)) -> 0.032914994 | G10: =INDEX(Scorecard!$Q$7:$Q$57,MATCH($B10,Scorecard!$P$7:$P$57,0)) -> A | H10: =IF(INDEX(Scorecard!$X$7:$X$57,MATCH($B10,Scorecard!$P$7:$P$57,0))="Check","Check","")
B11: 7 | C11: =INDEX(Scorecard!$B$7:$B$57,MATCH($B11,Scorecard!$P$7:$P$57,0)) -> Kentucky | D11: =INDEX(Scorecard!$O$7:$O$57,MATCH($B11,Scorecard!$P$7:$P$57,0)) -> 78.200024 | E11: =INDEX(Scorecard!$D$7:$D$57,MATCH($B11,Scorecard!$P$7:$P$57,0)) -> 2.8038922e+09 | F11: =INDEX(Scorecard!$G$7:$G$57,MATCH($B11,Scorecard!$P$7:$P$57,0)) -> 0.14581053 | G11: =INDEX(Scorecard!$Q$7:$Q$57,MATCH($B11,Scorecard!$P$7:$P$57,0)) -> A | H11: =IF(INDEX(Scorecard!$X$7:$X$57,MATCH($B11,Scorecard!$P$7:$P$57,0))="Check","Check","")
B12: 8 | C12: =INDEX(Scorecard!$B$7:$B$57,MATCH($B12,Scorecard!$P$7:$P$57,0)) -> Wisconsin | D12: =INDEX(Scorecard!$O$7:$O$57,MATCH($B12,Scorecard!$P$7:$P$57,0)) -> 74.700056 | E12: =INDEX(Scorecard!$D$7:$D$57,MATCH($B12,Scorecard!$P$7:$P$57,0)) -> 2.1464332e+09 | F12: =INDEX(Scorecard!$G$7:$G$57,MATCH($B12,Scorecard!$P$7:$P$57,0)) -> 0.020530131 | G12: =INDEX(Scorecard!$Q$7:$Q$57,MATCH($B12,Scorecard!$P$7:$P$57,0)) -> A | H12: =IF(INDEX(Scorecard!$X$7:$X$57,MATCH($B12,Scorecard!$P$7:$P$57,0))="Check","Check","")
B13: 9 | C13: =INDEX(Scorecard!$B$7:$B$57,MATCH($B13,Scorecard!$P$7:$P$57,0)) -> Ohio | D13: =INDEX(Scorecard!$O$7:$O$57,MATCH($B13,Scorecard!$P$7:$P$57,0)) -> 74.000042 | E13: =INDEX(Scorecard!$D$7:$D$57,MATCH($B13,Scorecard!$P$7:$P$57,0)) -> 4.778824e+09 | F13: =INDEX(Scorecard!$G$7:$G$57,MATCH($B13,Scorecard!$P$7:$P$57,0)) -> 0.028581539 | G13: =INDEX(Scorecard!$Q$7:$Q$57,MATCH($B13,Scorecard!$P$7:$P$57,0)) -> A | H13: =IF(INDEX(Scorecard!$X$7:$X$57,MATCH($B13,Scorecard!$P$7:$P$57,0))="Check","Check","")
B14: 10 | C14: =INDEX(Scorecard!$B$7:$B$57,MATCH($B14,Scorecard!$P$7:$P$57,0)) -> Missouri | D14: =INDEX(Scorecard!$O$7:$O$57,MATCH($B14,Scorecard!$P$7:$P$57,0)) -> 70.600032 | E14: =INDEX(Scorecard!$D$7:$D$57,MATCH($B14,Scorecard!$P$7:$P$57,0)) -> 2.041449e+09 | F14: =INDEX(Scorecard!$G$7:$G$57,MATCH($B14,Scorecard!$P$7:$P$57,0)) -> 0.087018042 | G14: =INDEX(Scorecard!$Q$7:$Q$57,MATCH($B14,Scorecard!$P$7:$P$57,0)) -> A | H14: =IF(INDEX(Scorecard!$X$7:$X$57,MATCH($B14,Scorecard!$P$7:$P$57,0))="Check","Check","")
B17: Headline
B18: ="The top 10 states hold "&TEXT(SUMPRODUCT((Scorecard!$P$7:$P$57<=10)*Scorecard!$D$7:$D$57)/Scorecard!$D$58,"0%")&" of reported spend in this selection." -> The top 10 states hold 44% of reported spend in this selection.
B19: ="Tier A ("&tier_a&" states) carries "&TEXT(SUMIFS(Scorecard!$D$7:$D$57,Scorecard!$Q$7:$Q$57,"A")/Scorecard!$D$58,"0%")&" of spend and "&TEXT((SUMIFS(Scorecard!$S$7:$S$57,Scorecard!$Q$7:$Q$57,"A")-SUMIFS(Scorecard!$D$7:$D$57,Scorecard!$Q$7:$Q$57,"A"))/(Scorecard!$S$58-Scorecard!$D$58),"0%")&" of the growth target." -> Tier A (10 states) carries 44% of spend and 54% of the growth target.
B20: ="National growth target: "&TEXT(target_growth,"0%")&" = "&TEXT(Scorecard!$S$58-Scorecard!$D$58,"$#,##0.0,,")&"M extra spend to win across the 51 states." -> National growth target: 8% = $8,568.0M extra spend to win across the 51 states.
B21: ="States flagged for a reporting break in this window: "&COUNTIF(Scorecard!$X$7:$X$57,"Check")&" (see the Reporting flag column)." -> States flagged for a reporting break in this window: 5 (see the Reporting flag column).
B24: Year | C24: National spend, selected area
B25: 2019 | C25: =SUMIFS(National!$C$2:$C$120,National!$A$2:$A$120,$B25,National!$B$2:$B$120,IF(sel_area="All areas","*",sel_area)) -> 7.3049293e+10
B26: 2020 | C26: =SUMIFS(National!$C$2:$C$120,National!$A$2:$A$120,$B26,National!$B$2:$B$120,IF(sel_area="All areas","*",sel_area)) -> 7.7713603e+10
B27: 2021 | C27: =SUMIFS(National!$C$2:$C$120,National!$A$2:$A$120,$B27,National!$B$2:$B$120,IF(sel_area="All areas","*",sel_area)) -> 8.7883139e+10
B28: 2022 | C28: =SUMIFS(National!$C$2:$C$120,National!$A$2:$A$120,$B28,National!$B$2:$B$120,IF(sel_area="All areas","*",sel_area)) -> 1.0007323e+11
B29: 2023 | C29: =SUMIFS(National!$C$2:$C$120,National!$A$2:$A$120,$B29,National!$B$2:$B$120,IF(sel_area="All areas","*",sel_area)) -> 1.1174237e+11
B30: 2024 | C30: =SUMIFS(National!$C$2:$C$120,National!$A$2:$A$120,$B30,National!$B$2:$B$120,IF(sel_area="All areas","*",sel_area)) -> 1.0831786e+11
B31: 2025 | C31: =SUMIFS(National!$C$2:$C$120,National!$A$2:$A$120,$B31,National!$B$2:$B$120,IF(sel_area="All areas","*",sel_area)) -> 1.1689157e+11

Sheet Checks
B1: Checks
B2: Every row should say OK. They run on every recalculation.
B4: Check | C4: Value | D4: Expected | E4: Result
B5: Weights in use add to 100% | C5: =Inputs!G21 -> 1 | D5: =1 -> 1 | E5: =IF(ABS(C5-D5)<0.000001,"OK","CHECK") -> OK
B6: State spend adds up to the Data sheet for this selection | C6: =Scorecard!D58 -> 1.0710013e+11 | D6: =SUMIFS(Data!$D$2:$D$6070,Data!$B$2:$B$6070,sel_year,Data!$C$2:$C$6070,IF(sel_area="All areas","*",sel_area)) -> 1.0710013e+11 | E6: =IF(ABS(C6-D6)<1,"OK","CHECK") -> OK
B7: Targets add up to base spend x (1 + growth target) | C7: =Scorecard!S58 -> 1.1566814e+11 | D7: =Scorecard!D58*(1+target_growth) -> 1.1566814e+11 | E7: =IF(ABS(C7-D7)<1,"OK","CHECK") -> OK
B8: Every state has a distinct rank 1-51 | C8: =SUMPRODUCT(1/COUNTIF(Scorecard!P7:P57,Scorecard!P7:P57)) -> 51 | D8: =51 -> 51 | E8: =IF(C8=D8,"OK","CHECK") -> OK
B9: No formula errors on the Scorecard | C9: =SUMPRODUCT(--ISERROR(Scorecard!D7:X57)) -> 0 | D9: =0 -> 0 | E9: =IF(C9=D9,"OK","CHECK") -> OK
B10: National Data total equals the National sheet (same selection) | C10: =SUMIFS(Data!$D$2:$D$6070,Data!$B$2:$B$6070,sel_year,Data!$C$2:$C$6070,IF(sel_area="All areas","*",sel_area)) -> 1.0710013e+11 | D10: =SUMIFS(National!$C$2:$C$120,National!$A$2:$A$120,sel_year,National!$B$2:$B$120,IF(sel_area="All areas","*",sel_area))*(1-0) -> 1.1689157e+11 | E10: =IF(C10<=D10+1,"OK","CHECK") -> OK
B11: Enrollment found for all 51 states in the base year | C11: =COUNTIFS(Enrollment!$B$2:$B$358,sel_year) -> 51 | D11: =51 -> 51 | E11: =IF(C11=D11,"OK","CHECK") -> OK
B13: Overall | C13: =IF(COUNTIF(E5:E11,"OK")=7,"All checks pass","Review the rows marked CHECK") -> All checks pass

Sheet Data
A1: state | B1: year | C1: area | D1: spend | E1: rx | F1: brand_spend
A2: AK | B2: 2019 | C2: Cardiovascular | D2: 5795005.1 | E2: 160032 | F2: 3134620.4
A3: AK | B3: 2019 | C3: Diabetes & obesity | D3: 14189091 | E3: 47281 | F3: 13909984
A4: AK | B4: 2019 | C4: Endocrine & women's health | D4: 5776646 | E4: 48884 | F4: 4513198.7
A5: AK | B5: 2019 | C5: Eye & skin | D5: 1434850 | E5: 5006 | F5: 1291180.6
A6: AK | B6: 2019 | C6: Gastroenterology | D6: 5909854.8 | E6: 74616 | F6: 2166484
A7: AK | B7: 2019 | C7: HIV | D7: 5964363.7 | E7: 2819 | F7: 5958904.5
A8: AK | B8: 2019 | C8: Hematology | D8: 3971312.5 | E8: 5915 | F8: 3887761
A9: AK | B9: 2019 | C9: Immunology & inflammation | D9: 24359048 | E9: 57275 | F9: 22768872
A10: AK | B10: 2019 | C10: Infectious disease (non-HIV) | D10: 14603825 | E10: 136988 | F10: 11041153
A11: AK | B11: 2019 | C11: Neurology & psychiatry | D11: 25288026 | E11: 351412 | F11: 17696778
A12: AK | B12: 2019 | C12: Oncology | D12: 9258064.8 | E12: 6320 | F12: 8742776.9
A13: AK | B13: 2019 | C13: Other (vitamins, fluids, diagnostics) | D13: 3001081.4 | E13: 27477 | F13: 153205.97
... A6070: WY | B6070: 2025 | C6070: Urology & renal | D6070: 85961.84 | E6070: 930 | F6070: 69115.11

Sheet Enrollment
A1: state | B1: year | C1: avg_enrollment
A2: AK | B2: 2019 | C2: 220536
A3: AK | B3: 2020 | C3: 231987
A4: AK | B4: 2021 | C4: 249696
A5: AK | B5: 2022 | C5: 261132
A6: AK | B6: 2023 | C6: 258267
A7: AK | B7: 2024 | C7: 250344
A8: AK | B8: 2025 | C8: 226314
A9: AL | B9: 2019 | C9: 913182
A10: AL | B10: 2020 | C10: 954312
A11: AL | B11: 2021 | C11: 1046266
A12: AL | B12: 2022 | C12: 1128279
A13: AL | B13: 2023 | C13: 1163731
... A358: WY | B358: 2025 | C358: 62025

Sheet National
A1: year | B1: area | C1: spend | D1: rx
A2: 2019 | B2: Cardiovascular | C2: 3.0087737e+09 | D2: 107534353
A3: 2019 | B3: Diabetes & obesity | C3: 7.0154414e+09 | D3: 30419783
A4: 2019 | B4: Endocrine & women's health | C4: 2.7950686e+09 | D4: 33767159
A5: 2019 | B5: Eye & skin | C5: 7.5466996e+08 | D5: 3484687
A6: 2019 | B6: Gastroenterology | C6: 1.8728168e+09 | D6: 42650480
A7: 2019 | B7: HIV | C7: 5.2128084e+09 | D7: 2450139
A8: 2019 | B8: Hematology | C8: 3.9337221e+09 | D8: 6379172
A9: 2019 | B9: Immunology & inflammation | C9: 6.3308185e+09 | D9: 29199763
A10: 2019 | B10: Infectious disease (non-HIV) | C10: 4.7563538e+09 | D10: 72840841
A11: 2019 | B11: Neurology & psychiatry | C11: 1.4931495e+10 | D11: 158788551
A12: 2019 | B12: Oncology | C12: 5.0889746e+09 | D12: 3013537
A13: 2019 | B13: Other (vitamins, fluids, diagnostics) | C13: 7.3883389e+08 | D13: 12027593
... A120: 2025 | B120: Urology & renal | C120: 6.3337289e+08 | D120: 3119433

Sheet Flags
A1: state | B1: year | C1: ffs_share | D1: yoy_change | E1: abs_yoy
A2: AK | B2: 2019 | C2: 1
A3: AK | B3: 2020 | C3: 1 | D3: -0.0421 | E3: =ABS(D3) -> 0.0421
A4: AK | B4: 2021 | C4: 1 | D4: 0.1743 | E4: =ABS(D4) -> 0.1743
A5: AK | B5: 2022 | C5: 1 | D5: 0.1888 | E5: =ABS(D5) -> 0.1888
A6: AK | B6: 2023 | C6: 1 | D6: 0.0218 | E6: =ABS(D6) -> 0.0218
A7: AK | B7: 2024 | C7: 1 | D7: -0.0191 | E7: =ABS(D7) -> 0.0191
A8: AK | B8: 2025 | C8: 0.9999 | D8: -0.015 | E8: =ABS(D8) -> 0.015
A9: AL | B9: 2019 | C9: 1
A10: AL | B10: 2020 | C10: 1 | D10: 0.0248 | E10: =ABS(D10) -> 0.0248
A11: AL | B11: 2021 | C11: 1 | D11: 0.1531 | E11: =ABS(D11) -> 0.1531
A12: AL | B12: 2022 | C12: 1 | D12: 0.0646 | E12: =ABS(D12) -> 0.0646
A13: AL | B13: 2023 | C13: 1 | D13: 0.0687 | E13: =ABS(D13) -> 0.0687
A14: AL | B14: 2024 | C14: 1 | D14: -0.0654 | E14: =ABS(D14) -> 0.0654
A15: AL | B15: 2025 | C15: 1 | D15: -0.0162 | E15: =ABS(D15) -> 0.0162
A16: AR | B16: 2019 | C16: 0.832
A17: AR | B17: 2020 | C17: 0.8058 | D17: -0.0051 | E17: =ABS(D17) -> 0.0051
A18: AR | B18: 2021 | C18: 0.7979 | D18: 0.0387 | E18: =ABS(D18) -> 0.0387
A19: AR | B19: 2022 | C19: 0.8091 | D19: 0.2135 | E19: =ABS(D19) -> 0.2135
A20: AR | B20: 2023 | C20: 0.8118 | D20: 0.0441 | E20: =ABS(D20) -> 0.0441
A21: AR | B21: 2024 | C21: 0.8167 | D21: -0.1233 | E21: =ABS(D21) -> 0.1233
A22: AR | B22: 2025 | C22: 0.8214 | D22: 0.0475 | E22: =ABS(D22) -> 0.0475
A23: AZ | B23: 2019 | C23: 0.0171
A24: AZ | B24: 2020 | C24: 0.0143 | D24: 0.1174 | E24: =ABS(D24) -> 0.1174
A25: AZ | B25: 2021 | C25: 0.0179 | D25: 0.0853 | E25: =ABS(D25) -> 0.0853
A26: AZ | B26: 2022 | C26: 0.0175 | D26: 0.1526 | E26: =ABS(D26) -> 0.1526
A27: AZ | B27: 2023 | C27: 0.0258 | D27: 0.0055 | E27: =ABS(D27) -> 0.0055
A28: AZ | B28: 2024 | C28: 0.0177 | D28: 0.0325 | E28: =ABS(D28) -> 0.0325
A29: AZ | B29: 2025 | C29: 0.0282 | D29: 0.0011 | E29: =ABS(D29) -> 0.0011
A30: CA | B30: 2019 | C30: 0.5153
A31: CA | B31: 2020 | C31: 0.5001 | D31: 0.0237 | E31: =ABS(D31) -> 0.0237
A32: CA | B32: 2021 | C32: 0.4975 | D32: 0.0945 | E32: =ABS(D32) -> 0.0945
A33: CA | B33: 2022 | C33: 0.9194 | D33: 0.2752 | E33: =ABS(D33) -> 0.2752
A34: CA | B34: 2023 | C34: 0.9068 | D34: 0.2319 | E34: =ABS(D34) -> 0.2319
A35: CA | B35: 2024 | C35: 0.9435 | D35: 0.0816 | E35: =ABS(D35) -> 0.0816
A36: CA | B36: 2025 | C36: 0.9626 | D36: 0.1282 | E36: =ABS(D36) -> 0.1282
A37: CO | B37: 2019 | C37: 0.9559
A38: CO | B38: 2020 | C38: 0.9572 | D38: 0.0722 | E38: =ABS(D38) -> 0.0722
A39: CO | B39: 2021 | C39: 0.9582 | D39: 0.1522 | E39: =ABS(D39) -> 0.1522
A40: CO | B40: 2022 | C40: 0.9578 | D40: 0.1252 | E40: =ABS(D40) -> 0.1252
...

Sheet Lists
A1: Areas | C1: Years | E1: Scenarios
A2: All areas | C2: 2019 | E2: Balanced
A3: Neurology & psychiatry | C3: 2020 | E3: Growth-led
A4: Immunology & inflammation | C4: 2021 | E4: Size-led
A5: Diabetes & obesity | C5: 2022 | E5: Custom
A6: Oncology | C6: 2023
A7: Respiratory & allergy | C7: 2024
A8: HIV | C8: 2025
A9: Rare & genetic disease
A10: Pain, addiction & anesthesia
A11: Cardiovascular
A12: Hematology
A13: Infectious disease (non-HIV)
A14: Endocrine & women's health
A15: Gastroenterology
A16: Unclassified
A17: Eye & skin
A18: Other (vitamins, fluids, diagnostics)
A19: Urology & renal
